Workbook

Sheet Sheet1
B2: Revenue
B3: Self-consumed electricity savings | C3: 133 882 kWh × €0.25/kWh | D3: 33470 | G3: Capex | H3: 265000 | L3: Year | M3: Capex | N3: OPEX | O3: Revenue | P3: Cash Flow | Q3: Cumilative Cashflow
B4: Digestate / fertiliser substitution | C4: 33.45 t × €400/t | D4: 13380 | L4: 2025 | M4: -265000 | P4: =M4 -> -265000 | Q4: =P4 -> -265000
B5: Avoided-emissions value | C5: 156.4 t CO₂e × €70/t | D5: 10945 | L5: 2026 | M5: 0 | N5: -10600 | O5: 57796 | P5: =O5+N5 -> 47196 | Q5: =Q4+P5 -> -217804
B6: Gross annual benefit | D6: 57796 | L6: 2027 | M6: 0 | N6: -10600 | O6: 57796 | P6: =O6+N6 -> 47196 | Q6: =Q5+P6 -> -170608
B7: O&M (Demonstrator, 4 % of €95k) | D7: -3800 | L7: 2028 | M7: 0 | N7: -10600 | O7: 57796 | P7: =O7+N7 -> 47196 | Q7: =Q6+P7 -> -123412
B8: O&M (EPC prototype, 4 % of €185k) | D8: -7400 | L8: 2029 | M8: 0 | N8: -10600 | O8: 57796 | P8: =O8+N8 -> 47196 | Q8: =Q7+P8 -> -76216
B9: O&M (Bankable, 4 % of €265k) | D9: -10600 | L9: 2030 | M9: 0 | N9: -10600 | O9: 57796 | P9: =O9+N9 -> 47196 | Q9: =Q8+P9 -> -29020
D10: =SUM(D3:D9) -> 93791 | L10: 2031 | M10: 0 | N10: -10600 | O10: 57796 | P10: =O10+N10 -> 47196 | Q10: =Q9+P10 -> 18176
L11: 2032 | M11: 0 | N11: -10600 | O11: 57796 | P11: =O11+N11 -> 47196 | Q11: =Q10+P11 -> 65372
L12: 2033 | M12: 0 | N12: -10600 | O12: 57796 | P12: =O12+N12 -> 47196 | Q12: =Q11+P12 -> 112568
L13: 2034 | M13: 0 | N13: -10600 | O13: 57796 | P13: =O13+N13 -> 47196 | Q13: =Q12+P13 -> 159764
B14: Discount rate | C14: 0.06 | L14: 2035 | M14: 0 | N14: -10600 | O14: 57796 | P14: =O14+N14 -> 47196 | Q14: =Q13+P14 -> 206960
L15: 2036 | M15: 0 | N15: -10600 | O15: 57796 | P15: =O15+N15 -> 47196 | Q15: =Q14+P15 -> 254156
L16: 2037 | M16: 0 | N16: -10600 | O16: 57796 | P16: =O16+N16 -> 47196 | Q16: =Q15+P16 -> 301352
L17: 2038 | M17: 0 | N17: -10600 | O17: 57796 | P17: =O17+N17 -> 47196 | Q17: =Q16+P17 -> 348548
L18: 2039 | M18: 0 | N18: -10600 | O18: 57796 | P18: =O18+N18 -> 47196 | Q18: =Q17+P18 -> 395744
L19: 2040 | M19: 0 | N19: -10600 | O19: 57796 | P19: =O19+N19 -> 47196 | Q19: =Q18+P19 -> 442940
L20: 2041 | M20: 0 | N20: -10600 | O20: 57796 | P20: =O20+N20 -> 47196 | Q20: =Q19+P20 -> 490136
L21: 2042 | M21: 0 | N21: -10600 | O21: 57796 | P21: =O21+N21 -> 47196 | Q21: =Q20+P21 -> 537332
L22: 2043 | M22: 0 | N22: -10600 | O22: 57796 | P22: =O22+N22 -> 47196 | Q22: =Q21+P22 -> 584528
L23: 2044 | M23: 0 | N23: -10600 | O23: 57796 | P23: =O23+N23 -> 47196 | Q23: =Q22+P23 -> 631724
L24: 2045 | M24: 0 | N24: -10600 | O24: 57796 | P24: =O24+N24 -> 47196 | Q24: =Q23+P24 -> 678920
L25: 2046 | M25: 0 | N25: -10600 | O25: 57796 | P25: =O25+N25 -> 47196 | Q25: =Q24+P25 -> 726116
K26: Total | M26: =+SUM(M4:M25) -> -265000 | N26: =+SUM(N4:N25) -> -222600 | O26: =+SUM(O4:O25) -> 1213716 | P26: =+SUM(P4:P25) -> 726116 | Q26: =+SUM(Q4:Q25) -> 5072276
H32: NPV | I32: =NPV(C14,P5:P25)+P4 -> 290217.36
H33: IRR | I33: =IRR(P4:P25) -> 0.17170894

Sheet Farm Energy Demand
A1: Labels | B1: Values | C1: Units | D1: Notes | E1: Source | G1: Labels | H1: Fuel per unit per year | I1: Total Fuel value | J1: Unit | K1: Fuel type | L1: Source
A2: Livestock Energy Use | G2: Dairy cow | H2: 120 | I2: =H2*'[1]Farm Inputs'!B7*H13 -> 58800 | J2: kWh/yr | K2: Diesel | L2: ✅
A3: Dairy cow | B3: =450*'[1]Farm Inputs'!B7 -> 22500 | C3: kWh/year | D3: Milking, ventilation, lighting, cooling | E3: ✅ | G3: Pig | H3: 3.8 | I3: =H3*'[1]Farm Inputs'!B8*H14 -> 1995 | J3: kWh/yr | K3: Diesel | L3: ✅
A4: Pig | B4: =70*'[1]Farm Inputs'!B8 -> 5250 | C4: kWh/year | D4: Ventilation, lighting, feeding systems | E4: ✅ | G4: Chicken | H4: 1.33 | I4: =H4*'[1]Farm Inputs'!B9*H14 -> 2793 | J4: kWh/yr | K4: Diesel | L4: ✅
A5: Chicken | B5: =5.2*'[1]Farm Inputs'!B9 -> 1560 | C5: kWh/year | D5: Lighting, ventilation | E5: ✅ | G5: Corn/Maize | H5: 140 | I5: =H5*'[1]Farm Inputs'!H3*H13 -> 20580 | J5: kWh/yr | K5: Diesel | L5: ✅
A6: Crop Processing Energy | G6: Wheat | H6: 100 | I6: =H6*'[1]Farm Inputs'!H2*H13 -> 34300 | J6: kWh/yr | K6: Diesel | L6: ✅
A7: Base rate | B7: 45 | C7: kWh/tonne | E7: ✅ | G7: Rapeseed | H7: 90 | I7: =H7*'[1]Farm Inputs'!H4*H13 -> 8820 | J7: kWh/yr | K7: Diesel | L7: ✅
A8: Seasonal adjustment | B8: 0.75 | D8: Active for 9 out of 12 months → multiply by 9/12 | G8: Total Fuel demand | I8: =SUM(I2:I7) -> 127288 | J8: kWh/yr | K8: Diesel | L8: ✅
A9: Crop processing energy (kWh) | B9: =B7*'[1]Farm Inputs'!$J$5*B8 -> 11643.75 | C9: kWh/year
A10: Irrigation Energy by Crop
A11: Rice | B11: 1850 | C11: kWh/ha·yr | E11: ✅
A12: Corn/Maize | B12: 2200 | C12: kWh/ha·yr | E12: ✅ | G12: Labels | H12: Value | I12: Unit
A13: Potatoes | B13: 1300 | C13: kWh/ha·yr | E13: ✅ | G13: Diesel | H13: 9.8 | I13: kWh/L
A14: Wheat | B14: 1200 | C14: kWh/ha·yr | D14: electric sprinkler, groundwater | E14: ✅ | G14: LPG/propane | H14: 7 | I14: kWh/L
A15: Barley | G15: Kerosene | H15: 9.5 | I15: kWh/L
A16: Rapeseed | B16: 1000 | C16: kWh/ha·yr | D16: either rainfed (0) or 500–800 kWh/ha in dry regions | E16: approximate from wheat values
A17: Sunflower
A18: Olives | G18: Annual direct on-farm energy split into ELECTRICITY (grid/power) and FUEL (diesel / LPG-propane / kerosene). Figures are research-based estimates from EU & comparable literature applied to this farm's headcounts and areas. Excludes indirect (embodied) energy in fertiliser & feed. Edit blue input cells to re-scale.
A19: Other crops
A20: Total irrigation energy | B20: =B12*'[1]Farm Inputs'!H3+B14*'[1]Farm Inputs'!H2+B16*'[1]Farm Inputs'!H4 -> 85000 | C20: kWh/year
A21: Base Infrastructure
A22: Fixed annual load | B22: 12250 | C22: kWh/year | D22: Office equipment, security lighting, gate motors, workshop tools | E22: This according to source is around 10% of annual energy demand. Calculated using other values
A23: Total Energy Demand | B23: =B3+B4+B5+B9+B20+B22 -> 138203.75 | C23: kWh/year

Sheet Farm Inputs
A1: Label | B1: Value | C1: Unit | D1: Notes | E1: Source | G1: Crop | H1: Area allocated (ha) | I1: Yield (tonnes/ha/year) | J1: Total production (tonnes/year) | K1: EF (kg CO₂e/kg) | L1: Total Emissions (t CO₂e) | M1: Nitrogen requirement (kg/ha) | N1: Phosphorus requirement (kg/ha) | O1: Potassium requirement (kg/ha) | P1: Fertilizer use rate (t/ha) | Q1: Total fertilizer use (tonnes) | R1: Source
A2: Total area | B2: 100 | C2: ha | G2: Wheat | H2: 35 | I2: 6 | J2: =H2*I2 -> 210 | K2: 0.3 | L2: =J2*K2 -> 63 | M2: 140 | N2: 39 | O2: 33 | P2: =MAX(M2/160,N2/160,O2/160) -> 0.875 | Q2: =P2*H2 -> 30.625 | R2: ✅
A3: Cultivated area | B3: 60 | C3: ha | G3: Grain maize | H3: 15 | I3: 7 | J3: =H3*I3 -> 105 | K3: 0.335 | L3: =J3*K3 -> 35.175 | M3: 154 | N3: 42 | O3: 35 | P3: =MAX(M3/160,N3/160,O3/160) -> 0.9625 | Q3: =P3*H3 -> 14.4375 | R3: ✅
A4: Area for cows | B4: 30 | C4: ha | G4: Rapeseed | H4: 10 | I4: 3 | J4: =H4*I4 -> 30 | K4: 1.2 | L4: =J4*K4 -> 36 | M4: 165 | N4: 82.5 | O4: 195 | P4: =MAX(M4/160,N4/160,O4/160) -> 1.21875 | Q4: =P4*H4 -> 12.1875 | R4: ✅
A5: Area for pigs | B5: 5 | C5: ha | G5: Total | H5: =SUM(H2:H4) -> 60 | J5: =SUM(J2:J4) -> 345 | K5: =SUM('Farm Inputs'!$K$2:$K$4) -> 1.835 | L5: =SUM(L2:L4) -> 134.175 | P5: =SUM('Farm Inputs'!$P$2:$P$4) -> 3.05625 | Q5: =SUM('Farm Inputs'!$Q$2:$Q$4) -> 57.25
A6: Area for chickens | B6: 1 | C6: ha
A7: Number of cows | B7: 50 | C7: head count | E7: ✅ | M7: NPK equivalent
A8: Number of pigs | B8: 75 | C8: head count | E8: ✅ | G8: Label | H8: Value | I8: Unit | J8: Notes | K8: Source | M8: Label | N8: Value | O8: Unit | P8: Label | Q8: Value | R8: Unit | S8: Label | T8: Value | U8: Unit
A9: Number of chickens | B9: 300 | C9: head count | E9: ✅ | G9: Cow manure per day | H9: 60 | I9: kg/day | K9: ✅ | M9: Wheat | P9: Grain maize | S9: Rapeseed
A10: Milk yield per cow | B10: 8000 | C10: kg/year | E10: ✅ | G10: Pig manure per day | H10: 5 | I10: kg/day | K10: ✅ | M10: N_res | N10: =M2-H38 -> 128.80795 | O10: kg/ha | P10: N_res | Q10: =M3-H38 -> 142.80795 | R10: kg/ha | S10: N_res | T10: =M4-H38 -> 153.80795 | U10: kg/ha
A11: Total Milk yield | B11: =B10*B7 -> 400000 | C11: kg/year | G11: Chicken manure per day | H11: 0.15 | I11: kg/day | K11: ✅ | M11: P_res | N11: =N2-H39 -> 33.714864 | O11: kg/ha | P11: P_res | Q11: =N3-H39 -> 36.714864 | R11: kg/ha | S11: P_res | T11: =N4-H39 -> 77.214864 | U11: kg/ha
A12: Milk EF | B12: 1.04 | C12: kg CO₂e per kg | E12: ✅ | G12: Total cow manure per year | H12: =H9*B7*365/1000 -> 1095 | I12: tonnes/year | M12: K_res | N12: =MAX(O2-H40,0) -> 19.320825 | O12: kg/ha | P12: K_res | Q12: =MAX(O3-H40,0) -> 21.320825 | R12: kg/ha | S12: K_res | T12: =MAX(O4-H40,0) -> 181.32082 | U12: kg/ha
A13: Crop yield | B13: =J5*1000 -> 345000 | C13: kg/year | G13: Total pig manure per year | H13: =H10*B8*365/1000 -> 136.875 | I13: tonnes/year | M13: 16‑16‑16 needed per ha: | P13: 16‑16‑16 needed per ha: | S13: 16‑16‑16 needed per ha:
A14: Diesel price | G14: Total chicken manure per year | H14: =H11*B9*365/1000 -> 16.425 | I14: tonnes/year | M14: N | N14: =N10/160 -> 0.80504967 | O14: t/ha | P14: N | Q14: =Q10/160 -> 0.89254967 | R14: t/ha | S14: N | T14: =T10/160 -> 0.96129967 | U14: t/ha
A15: Electriciy price | B15: 0.25 | C15: €/kWh | D15: farm as a commercial user | E15: ✅ | G15: Total manure per year | H15: =SUM(H12:H14) -> 1248.3 | I15: tonnes/year | M15: P | N15: =N11/160 -> 0.2107179 | O15: t/ha | P15: P | Q15: =Q11/160 -> 0.2294679 | R15: t/ha | S15: P | T15: =T11/160 -> 0.4825929 | U15: t/ha
A16: FiB total annual electricity | B16: =B32+H31 -> 95424.039 | C16: kWh/year | M16: K | N16: =N12/160 -> 0.12075515 | P16: K | Q16: =Q12/160 -> 0.13325515 | S16: K | T16: =T12/160 -> 1.1332552
A17: European average grid intensity | B17: 0.25 | C17: kgCO₂e/kWh | E17: ✅ | M17: Rate | N17: =MAX(N14,N15,N16) -> 0.80504967 | O17: t/ha | P17: Rate | Q17: =MAX(Q14,Q15,Q16) -> 0.89254967 | R17: t/ha | S17: Rate | T17: =MAX(T14,T15,T16) -> 1.1332552 | U17: t/ha
A18: Grid export revenue | B18: 0.07 | C18: €/kWh | D18: sits between low Belgian surplus tariffs (~0.03 €/kWh) and German/Italian small‑PV FiTs (0.07–0.12 €/kWh) | E18: ✅ | G18: Label | H18: Value | I18: Unit | J18: Notes | K18: Source | M18: Total fertilizer needed after digestate | N18: =N17*H2*0.45 -> 12.679532 | O18: t/year | P18: Total fertilizer needed after digestate | Q18: =Q17*H3*0.45 -> 6.0247103 | R18: t/year | S18: Total fertilizer needed after digestate | T18: =T17*H4*0.45 -> 5.0996482 | U18: t/year
A19: Grid export limit | B19: 100 | C19: kW | E19: ✅ | G19: Cow biogas yield | H19: 0.04 | I19: m³/kg manure | K19: ✅ | P19: Total | Q19: =(N18+Q18+T18) -> 23.803891 | R19: t/year
A20: Carbon price high | B20: 75 | C20: €/tCO₂ avoided | E20: ✅ | G20: Pig biogas yield | H20: 0.06 | I20: m³/kg manure | K20: ✅ | P20: New fertiliser cost | Q20: =Q19*B42 -> 9521.5563 | R20: €/year
A21: Carbon price low | B21: 10 | C21: €/tCO₂ avoided | E21: ✅ | G21: Chicken biogas yield | H21: 0.07 | I21: m³/kg manure | K21: ✅
G22: Daily biogas from cow | H22: =H19*H9*B7*H49 -> 42.105263 | I22: m³/day
G23: Daily biogas from pig | H23: =H20*H10*B8*H49 -> 7.8947368 | I23: m³/day | M23: Label | N23: Value | O23: Unit | P23: Notes | Q23: Source
G24: Daily biogas from chicken | H24: =H21*H11*B9*H49 -> 1.1052632 | I24: m³/day | M24: Cow VS excretion rate | N24: 8.4 | O24: kg VS/1000kg AM/day | Q24: ✅
A25: Label | B25: Value | C25: Unit | D25: Notes | E25: Source | G25: Total daily biogas | H25: =SUM(H22:H24) -> 51.105263 | I25: m³/day | M25: Pig VS excretion rate | N25: 4.5 | O25: kg VS/1000kg AM/day | Q25: ✅
A26: Solar panel power | B26: 400 | C26: W | E26: ✅ | G26: Annual biogas | H26: =H25*365 -> 18653.421 | I26: m³/year | M26: Chicken VS excretion rate | N26: 12.3 | O26: kg VS/1000kg AM/day | Q26: ✅
A27: Dimensions | B27: 1.95 | C27: m² | D27: 1.72 m × 1.13 m ≈ 1.95 m² | E27: ✅ | G27: Energy in biogas | H27: 6 | I27: kWh/m³ of biogas | J27: standard calorific value | M27: Cow Nitrogen excretion rate | N27: 0.54 | O27: kg N/1000kg AM/day | Q27: ✅
A28: Area per kWp | B28: =1000/(B26/B27) -> 4.875 | C28: m²/kWp | G28: Generator efficiency | H28: 0.35 | I28: % | J28: typical small-farm CHP unit | M28: Pig Nitrogen excretion rate | N28: 0.65 | O28: kg N/1000kg AM/day | Q28: ✅
A29: Solar panel area | B29: =B33*B28 -> 243.75 | C29: m² | G29: Raw electricity output | H29: =H26*H27*H28 -> 39172.184 | I29: kWh/year | M29: Chicken Nitrogen excretion rate | N29: 0.99 | O29: kg N/1000kg AM/day | Q29: ✅
A30: Solar panel efficiency | B30: 0.21 | C30: % | D30: 20.8 % Trina Solar Vertex S 400 W module monocrystalline panel | G30: Parasitic fraction | H30: =MIN(0.2 + 0.1 * (5 - 0) / 15, 0.3) -> 0.23333333 | J30: Assumed winter temperature to be 0 deg. Can work with other options in sensitivity analysis | M30: Cow weight | N30: 600 | O30: kg | Q30: ✅
A31: Default solar irradiance | B31: 3.5 | C31: kWh/m²/day | D31: 1280 kWh/m²/year, between north and south EU, consistent with PVGIS ranges | E31: ✅ | G31: Net electricity output | H31: =H29*(1-H30) -> 30032.008 | I31: kWh/year | M31: Pig weight | N31: 76 | O31: kg | Q31: ✅
A32: Annual solar output | B32: =B29*B30*B31*365 -> 65392.031 | C32: kWh/year | M32: Chicken weight | N32: 1.4 | O32: kg | Q32: ✅
A33: Peak power of panels | B33: 50 | C33: kWp | M33: Cow Annual VS | N33: =N24*(N30/1000)*365*B7 -> 91980 | O33: kg VS/year
A34: Recommended battery | B34: =B33*3 -> 150 | C34: kWh | D34: The 1:3 ratio (kWp to kWh) is a common industry guideline for farms wanting to maximise overnight self-consumption | G34: Label | H34: Value | I34: Unit | J34: Notes | K34: Source | M34: Pig Annual VS | N34: =N25*(N31/1000)*365*B8 -> 9362.25 | O34: kg VS/year
A35: PV capacity factor (Grid export CF) | B35: 0.14 | C35: % | D35: Annual generation 2,750 TWh ÷ (Rooftop PV potential 2.3 TW × 8,760 h) | E35: ✅ | G35: Total N | H35: 3.6 | I35: kg N/m³ | K35: ✅ | M35: Chicken Annual VS | N35: =N26*(N32/1000)*365*B9 -> 1885.59 | O35: kg VS/year
G36: Total P₂O₅ | H36: 1.7 | I36: kg P₂O₅/m³ | K36: ✅ | M36: Cow Annual N | N36: =N27*(N30/1000)*365*B7 -> 5913 | O36: kg N/year
G37: Total K₂O | H37: 4.4 | I37: kg K₂O/m³ | K37: ✅ | M37: Pig Annual N | N37: =N28*(N31/1000)*365*B8 -> 1352.325 | O37: kg N/year
A38: Label | B38: Value | C38: Unit | D38: Notes | E38: Source | G38: N from digestate per ha | H38: =H35*B53 -> 11.192053 | I38: kg N/ha | K38: ✅ | M38: Chicken Annual N | N38: =N29*(N32/1000)*365*B9 -> 151.767 | O38: kg N/year
A39: Fertilized area | B39: 55 | C39: ha | G39: P₂O₅ from digestate per ha | H39: =H36*B53 -> 5.285136 | I39: kg P₂O₅/ha | K39: ✅ | M39: Total annual excretion VS | N39: =SUM(N33:N35) -> 103227.84 | O39: kg VS/year
A40: Fertilizer grade reference | B40: 16‑16‑16 | E40: ✅ | G40: K₂O from digestate per ha | H40: =H37*B53 -> 13.679175 | I40: kg K₂O/ha | K40: ✅ | M40: Total annual excretion N | N40: =SUM(N36:N38) -> 7417.092 | O40: kg N/year
...

Sheet Finances
B2: Energy conversion subsystem | E2: Biochemical, thermal, water and digestate subsystem
B3: Item | C3: Indicative cost (€) | E3: Item | F3: Indicative cost (€)
B4: Solar PV modules and mounting | C4: 40000 | E4: Feedstock intake, mixing pit and screen | F4: 6000
B5: MPPT controllers and hybrid inverter | C5: 6000 | E5: Chopper and slurry feed pumps | F5: 10000
B6: Lithium-ion BESS | C6: 10500 | E6: Tubular digester (installed) | F6: 45000
B7: Distribution, metering and HVAC | C7: 1500 | E7: Gas conditioning, regulator and flare | F7: 16000
B8: Micro-CHP engine (biogas) | C8: 20000 | E8: Solid–liquid separator | F8: 15000
B9: Subsystem subtotal | C9: 78000 | E9: Digestate storage and thermal manifold | F9: 12000
E10: Rainwater tank and booster pump | F10: 1500
E11: Subsystem subtotal | F11: 105500
B14: Control, telemetry and instrumentation subsystem | E14: labour, installation, commissioning, contingency, and VAT
B15: Item | C15: Indicative cost (€) | E15: =265000-F11-C9-C20 -> 74000
B16: PLC, HMI and IIoT/cellular gateway | C16: 1000
B17: Process instrumentation | C17: 3500
B18: Energy meters, VFDs and battery monitor | C18: 1500
B19: Actuated valves, gas safety and engine control | C19: 1500
B20: Subsystem subtotal | C20: 7500
B26: FINAL CAPEX For On ground System | E26: OPEX Considering a general 4% of CAPEX
B27: Cost element | C27: Euros (€) | E27: =0.04*C33 -> 10600
B28: Solar PV (50 kWp) | C28: 42000
B29: BESS | C29: 12000
B30: Digester + CHP | C30: 150000 | E30: Cash-flow component | F30: Calculation | G30: Value (€/yr)
B31: Controls and instrumentation | C31: 9000 | E31: Self-consumed electricity savings | F31: 133 882 kWh × €0.25/kWh | G31: 33470
B32: BoP, install, contingency | C32: 52000 | E32: Digestate / fertiliser substitution | F32: 33.45 t × €400/t | G32: 13380
B33: Total CAPEX | C33: 265000 | E33: Avoided-emissions value | F33: 156.4 t CO₂e × €70/t | G33: 10945
E34: Gross annual benefit | G34: 57796

Sheet Calculations
B3: Year | C3: CAPEX | D3: OPEX | E3: EXPENSE | F3: REVENUE | G3: CASH FLOW | H3: CUMILATIVE CASH FLOW
A4: 1 | B4: 2026 | C4: =-(Finances!C33) -> -265000 | D4: 0 | E4: =D4+C4 -> -265000 | F4: 0 | G4: =F4+E4 -> -265000 | H4: =G4 -> -265000 | J4: Discount Rate | K4: 0.06 | M4: Discount Rate | N4: 0.08 | P4: Discount Rate | Q4: 0.1
A5: 2 | B5: 2027 | C5: 0 | D5: =-(Finances!E27) -> -10600 | E5: =D5+C5 -> -10600 | F5: =Finances!G34 -> 57796 | G5: =F5+E5 -> 47196 | H5: =G5+H4 -> -217804
A6: 3 | B6: 2028 | C6: 0 | D6: =-(Finances!E27) -> -10600 | E6: =D6+C6 -> -10600 | F6: 57796 | G6: =F6+E6 -> 47196 | H6: =H5+G6 -> -170608 | J6: NPV | K6: =NPV(K4,G5:G24)+G4 -> 276334.4 | M6: NPV | N6: =NPV(N4,G5:G24)+G4 -> 198377.29 | P6: NPV | Q6: =NPV(Q4,G5:G24)+G4 -> 136806.15
A7: 4 | B7: 2029 | C7: 0 | D7: -10600 | E7: =D7+C7 -> -10600 | F7: 57796 | G7: =F7+E7 -> 47196 | H7: =H6+G7 -> -123412 | J7: IRR | K7: =IRR(G4:G24) -> 0.17044903
A8: 5 | B8: 2030 | C8: 0 | D8: -10600 | E8: =D8+C8 -> -10600 | F8: 57796 | G8: =F8+E8 -> 47196 | H8: =H7+G8 -> -76216
A9: 6 | B9: 2031 | C9: 0 | D9: -10600 | E9: =D9+C9 -> -10600 | F9: 57796 | G9: =F9+E9 -> 47196 | H9: =H8+G9 -> -29020
A10: 7 | B10: 2032 | C10: 0 | D10: -10600 | E10: =D10+C10 -> -10600 | F10: 57796 | G10: =F10+E10 -> 47196 | H10: =H9+G10 -> 18176
A11: 8 | B11: 2033 | C11: 0 | D11: -10600 | E11: =D11+C11 -> -10600 | F11: 57796 | G11: =F11+E11 -> 47196 | H11: =H10+G11 -> 65372
A12: 9 | B12: 2034 | C12: 0 | D12: -10600 | E12: =D12+C12 -> -10600 | F12: 57796 | G12: =F12+E12 -> 47196 | H12: =H11+G12 -> 112568
A13: 10 | B13: 2035 | C13: 0 | D13: -10600 | E13: =D13+C13 -> -10600 | F13: 57796 | G13: =F13+E13 -> 47196 | H13: =H12+G13 -> 159764
A14: 11 | B14: 2036 | C14: 0 | D14: -10600 | E14: =D14+C14 -> -10600 | F14: 57796 | G14: =F14+E14 -> 47196 | H14: =H13+G14 -> 206960
A15: 12 | B15: 2037 | C15: 0 | D15: -10600 | E15: =D15+C15 -> -10600 | F15: 57796 | G15: =F15+E15 -> 47196 | H15: =H14+G15 -> 254156
A16: 13 | B16: 2038 | C16: 0 | D16: -10600 | E16: =D16+C16 -> -10600 | F16: 57796 | G16: =F16+E16 -> 47196 | H16: =H15+G16 -> 301352
A17: 14 | B17: 2039 | C17: 0 | D17: -10600 | E17: =D17+C17 -> -10600 | F17: 57796 | G17: =F17+E17 -> 47196 | H17: =H16+G17 -> 348548
A18: 15 | B18: 2040 | C18: 0 | D18: -10600 | E18: =D18+C18 -> -10600 | F18: 57796 | G18: =F18+E18 -> 47196 | H18: =H17+G18 -> 395744
A19: 16 | B19: 2041 | C19: 0 | D19: -10600 | E19: =D19+C19 -> -10600 | F19: 57796 | G19: =F19+E19 -> 47196 | H19: =H18+G19 -> 442940
... A24: 21 | B24: 2046 | C24: 0 | D24: -10600 | E24: =D24+C24 -> -10600 | F24: 57796 | G24: =F24+E24 -> 47196 | H24: =H23+G24 -> 678920
B29: Discount Rate | C29: NPV
B30: =K4 -> 0.06 | C30: =K6 -> 276334.4
B31: =N4 -> 0.08 | C31: =N6 -> 198377.29
B32: =Q4 -> 0.1 | C32: =Q6 -> 136806.15
